<?xml version="1.0"?>
<robot name="simple_robot">

  <!-- ====================== 底盘 ====================== -->
  <link name="base_link">
    <visual>
      <geometry>
        <box size="0.4 0.2 0.1"/>
      </geometry>
      <origin xyz="0 0 0.05"/>
      <material name="blue">
        <color rgba="0 0 0.8 1"/>
      </material>
    </visual>

    <!-- 必须加：碰撞 -->
    <collision>
      <geometry>
        <box size="0.4 0.2 0.1"/>
      </geometry>
      <origin xyz="0 0 0.05"/>
    </collision>

    <!-- 必须加：惯性 -->
    <inertial>
      <mass value="0.5"/>
      <inertia ixx="0.01" ixy="0" ixz="0" iyy="0.01" iyz="0" izz="0.01"/>
    </inertial>
  </link>

  <!-- ====================== 左轮 ====================== -->
  <link name="wheel_left_link">
    <visual>
      <geometry>
        <cylinder length="0.04" radius="0.1"/>
      </geometry>
      <origin rpy="1.5708 0 0"/>
      <material name="black">
        <color rgba="0 0 0 1"/>
      </material>
    </visual>

    <collision>
      <geometry>
        <cylinder length="0.04" radius="0.1"/>
      </geometry>
      <origin rpy="1.5708 0 0"/>
    </collision>

    <inertial>
      <mass value="0.05"/>
      <inertia ixx="0.0001" ixy="0" ixz="0" iyy="0.0001" iyz="0" izz="0.0001"/>
    </inertial>
  </link>

  <joint name="wheel_left_joint" type="continuous">
    <parent link="base_link"/>
    <child link="wheel_left_link"/>
    <origin xyz="-0.15 -0.15 0"/>
    <axis xyz="0 1 0"/>
  </joint>

  <!-- ====================== 右轮 ====================== -->
  <link name="wheel_right_link">
    <visual>
      <geometry>
        <cylinder length="0.04" radius="0.1"/>
      </geometry>
      <origin rpy="1.5708 0 0"/>
      <material name="black">
        <color rgba="0 0 0 1"/>
      </material>
    </visual>

    <collision>
      <geometry>
        <cylinder length="0.04" radius="0.1"/>
      </geometry>
      <origin rpy="1.5708 0 0"/>
    </collision>

    <inertial>
      <mass value="0.05"/>
      <inertia ixx="0.0001" ixy="0" ixz="0" iyy="0.0001" iyz="0" izz="0.0001"/>
    </inertial>
  </link>

  <joint name="wheel_right_joint" type="continuous">
    <parent link="base_link"/>
    <child link="wheel_right_link"/>
    <origin xyz="-0.15 0.15 0"/>
    <axis xyz="0 1 0"/>
  </joint>

  <!-- ====================== 万向轮 ====================== -->
  <link name="caster_link">
    <visual>
      <geometry>
        <sphere radius="0.05"/>
      </geometry>
      <material name="gray">
        <color rgba="0.5 0.5 0.5 1"/>
      </material>
    </visual>

    <collision>
      <geometry>
        <sphere radius="0.05"/>
      </geometry>
    </collision>

    <inertial>
      <mass value="0.02"/>
      <inertia ixx="0.00001" ixy="0" ixz="0" iyy="0.00001" iyz="0" izz="0.00001"/>
    </inertial>
  </link>

  <joint name="caster_joint" type="fixed">
    <parent link="base_link"/>
    <child link="caster_link"/>
    <origin xyz="0.2 0 0"/>
  </joint>

<!-- ====================== GAZEBO 驱动插件（最终完美版） ====================== -->
<gazebo>
  <plugin name="differential_drive_controller" filename="libgazebo_ros_diff_drive.so">
    <alwaysOn>true</alwaysOn>
    <updateRate>100</updateRate>

    <!-- 左右轮互换 → 转向正确！-->
    <leftJoint>wheel_right_joint</leftJoint>
    <rightJoint>wheel_left_joint</rightJoint>

    <wheelSeparation>0.3</wheelSeparation>
    <wheelDiameter>0.2</wheelDiameter>
    <wheelTorque>20</wheelTorque>

    <!-- 关闭加速度渐变 → 按下就动，不拖泥带水！-->
    <wheelAcceleration>0</wheelAcceleration>
    <wheelDeceleration>0</wheelDeceleration>

    <commandTopic>cmd_vel</commandTopic>
    <odometryTopic>odom</odometryTopic>
    <odometryFrame>odom</odometryFrame>
    <robotBaseFrame>base_link</robotBaseFrame>
  </plugin>
</gazebo>


</robot>

